<?xml version="1.0"?>
<robot name="diffbot">

  <!-- Base -->
  <link name="base_link">
    <visual>
      <geometry>
        <box size="0.4 0.3 0.1"/>
      </geometry>
    </visual>
    <collision>
      <geometry>
        <box size="0.4 0.3 0.1"/>
      </geometry>
    </collision>
    <inertial>
      <mass value="6.0"/>
      <origin xyz="0 0 0"/>
      <inertia ixx="0.1" iyy="0.1" izz="0.1"
               ixy="0" ixz="0" iyz="0"/>
    </inertial>
  </link>

  <!-- Left wheel -->
  <link name="left_wheel">
    <visual>
      <!-- Rotate cylinder so it spins around Y -->
      <origin rpy="-1.5708 0 0"/>
      <geometry>
        <cylinder radius="0.05" length="0.03"/>
      </geometry>
    </visual>
    <collision>
      <origin rpy="-1.5708 0 0"/>
      <geometry>
        <cylinder radius="0.05" length="0.03"/>
      </geometry>
    </collision>
    <inertial>
      <mass value="0.3"/>
      <origin xyz="0 0 0"/>
      <inertia ixx="0.001" iyy="0.001" izz="0.001"
               ixy="0" ixz="0" iyz="0"/>
    </inertial>
  </link>

  <!-- Right wheel -->
  <link name="right_wheel">
    <visual>
      <origin rpy="-1.5708 0 0"/>
      <geometry>
        <cylinder radius="0.05" length="0.03"/>
      </geometry>
    </visual>
    <collision>
      <origin rpy="-1.5708 0 0"/>
      <geometry>
        <cylinder radius="0.05" length="0.03"/>
      </geometry>
    </collision>
    <inertial>
      <mass value="0.3"/>
      <origin xyz="0 0 0"/>
      <inertia ixx="0.001" iyy="0.001" izz="0.001"
               ixy="0" ixz="0" iyz="0"/>
    </inertial>
  </link>

  <!-- Joints -->
  <joint name="left_wheel_joint" type="continuous">
    <parent link="base_link"/>
    <child link="left_wheel"/>
    <origin xyz="0 0.15 -0.05"/>
    <axis xyz="0 1 0"/>
  </joint>

  <joint name="right_wheel_joint" type="continuous">
    <parent link="base_link"/>
    <child link="right_wheel"/>
    <origin xyz="0 -0.15 -0.05"/>
    <axis xyz="0 1 0"/>
  </joint>

  <!-- Gazebo diff drive -->
  <gazebo>
    <plugin name="diff_drive" filename="libgazebo_ros_diff_drive.so">
      <left_joint>left_wheel_joint</left_joint>
      <right_joint>right_wheel_joint</right_joint>

      <wheel_separation>0.30</wheel_separation>
      <wheel_diameter>0.10</wheel_diameter>

      <robot_base_frame>base_link</robot_base_frame>
      <odometry_frame>odom</odometry_frame>

      <publish_odom>true</publish_odom>
      <publish_odom_tf>true</publish_odom_tf>

      <update_rate>50</update_rate>
    </plugin>
  </gazebo>

</robot>
